{
    DataVersion: 3955,
    size: [5, 5, 5],
    data: [
        {pos: [0, 0, 0], state: "minecraft:bedrock"},
        {pos: [0, 0, 1], state: "minecraft:bedrock"},
        {pos: [0, 0, 2], state: "minecraft:bedrock"},
        {pos: [0, 0, 3], state: "minecraft:bedrock"},
        {pos: [0, 0, 4], state: "minecraft:bedrock"},
        {pos: [1, 0, 0], state: "minecraft:bedrock"},
        {pos: [1, 0, 1], state: "minecraft:bedrock"},
        {pos: [1, 0, 2], state: "technicresources:glowrock"},
        {pos: [1, 0, 3], state: "minecraft:bedrock"},
        {pos: [1, 0, 4], state: "minecraft:bedrock"},
        {pos: [2, 0, 0], state: "minecraft:bedrock"},
        {pos: [2, 0, 1], state: "technicresources:glowrock"},
        {pos: [2, 0, 2], state: "technicresources:bedrock_room_manager{stage:0}"},
        {pos: [2, 0, 3], state: "technicresources:glowrock"},
        {pos: [2, 0, 4], state: "minecraft:bedrock"},
        {pos: [3, 0, 0], state: "minecraft:bedrock"},
        {pos: [3, 0, 1], state: "minecraft:bedrock"},
        {pos: [3, 0, 2], state: "technicresources:glowrock"},
        {pos: [3, 0, 3], state: "minecraft:bedrock"},
        {pos: [3, 0, 4], state: "minecraft:bedrock"},
        {pos: [4, 0, 0], state: "minecraft:bedrock"},
        {pos: [4, 0, 1], state: "minecraft:bedrock"},
        {pos: [4, 0, 2], state: "minecraft:bedrock"},
        {pos: [4, 0, 3], state: "minecraft:bedrock"},
        {pos: [4, 0, 4], state: "minecraft:bedrock"},
        {pos: [0, 1, 0], state: "minecraft:bedrock"},
        {pos: [0, 1, 1], state: "minecraft:bedrock"},
        {pos: [0, 1, 2], state: "minecraft:bedrock"},
        {pos: [0, 1, 3], state: "minecraft:bedrock"},
        {pos: [0, 1, 4], state: "minecraft:bedrock"},
        {pos: [1, 1, 0], state: "minecraft:bedrock"},
        {pos: [1, 1, 1], state: "minecraft:air"},
        {pos: [1, 1, 2], state: "minecraft:air"},
        {pos: [1, 1, 3], state: "minecraft:air"},
        {pos: [1, 1, 4], state: "minecraft:bedrock"},
        {pos: [2, 1, 0], state: "minecraft:bedrock"},
        {pos: [2, 1, 1], state: "minecraft:air"},
        {pos: [2, 1, 2], state: "minecraft:air"},
        {pos: [2, 1, 3], state: "minecraft:air"},
        {pos: [2, 1, 4], state: "minecraft:bedrock"},
        {pos: [3, 1, 0], state: "minecraft:bedrock"},
        {pos: [3, 1, 1], state: "minecraft:air"},
        {pos: [3, 1, 2], state: "minecraft:air"},
        {pos: [3, 1, 3], state: "minecraft:air"},
        {pos: [3, 1, 4], state: "minecraft:bedrock"},
        {pos: [4, 1, 0], state: "minecraft:bedrock"},
        {pos: [4, 1, 1], state: "minecraft:bedrock"},
        {pos: [4, 1, 2], state: "minecraft:bedrock"},
        {pos: [4, 1, 3], state: "minecraft:bedrock"},
        {pos: [4, 1, 4], state: "minecraft:bedrock"},
        {pos: [0, 2, 0], state: "minecraft:bedrock"},
        {pos: [0, 2, 1], state: "minecraft:bedrock"},
        {pos: [0, 2, 2], state: "minecraft:bedrock"},
        {pos: [0, 2, 3], state: "minecraft:bedrock"},
        {pos: [0, 2, 4], state: "minecraft:bedrock"},
        {pos: [1, 2, 0], state: "minecraft:bedrock"},
        {pos: [1, 2, 1], state: "minecraft:air"},
        {pos: [1, 2, 2], state: "minecraft:air"},
        {pos: [1, 2, 3], state: "minecraft:air"},
        {pos: [1, 2, 4], state: "minecraft:bedrock"},
        {pos: [2, 2, 0], state: "minecraft:bedrock"},
        {pos: [2, 2, 1], state: "minecraft:air"},
        {pos: [2, 2, 2], state: "minecraft:air"},
        {pos: [2, 2, 3], state: "minecraft:air"},
        {pos: [2, 2, 4], state: "minecraft:bedrock"},
        {pos: [3, 2, 0], state: "minecraft:bedrock"},
        {pos: [3, 2, 1], state: "minecraft:air"},
        {pos: [3, 2, 2], state: "minecraft:air"},
        {pos: [3, 2, 3], state: "minecraft:air"},
        {pos: [3, 2, 4], state: "minecraft:bedrock"},
        {pos: [4, 2, 0], state: "minecraft:bedrock"},
        {pos: [4, 2, 1], state: "minecraft:bedrock"},
        {pos: [4, 2, 2], state: "minecraft:bedrock"},
        {pos: [4, 2, 3], state: "minecraft:bedrock"},
        {pos: [4, 2, 4], state: "minecraft:bedrock"},
        {pos: [0, 3, 0], state: "minecraft:bedrock"},
        {pos: [0, 3, 1], state: "minecraft:bedrock"},
        {pos: [0, 3, 2], state: "minecraft:bedrock"},
        {pos: [0, 3, 3], state: "minecraft:bedrock"},
        {pos: [0, 3, 4], state: "minecraft:bedrock"},
        {pos: [1, 3, 0], state: "minecraft:bedrock"},
        {pos: [1, 3, 1], state: "minecraft:air"},
        {pos: [1, 3, 2], state: "minecraft:air"},
        {pos: [1, 3, 3], state: "minecraft:air"},
        {pos: [1, 3, 4], state: "minecraft:bedrock"},
        {pos: [2, 3, 0], state: "minecraft:bedrock"},
        {pos: [2, 3, 1], state: "minecraft:air"},
        {pos: [2, 3, 2], state: "minecraft:air"},
        {pos: [2, 3, 3], state: "minecraft:air"},
        {pos: [2, 3, 4], state: "minecraft:bedrock"},
        {pos: [3, 3, 0], state: "minecraft:bedrock"},
        {pos: [3, 3, 1], state: "minecraft:air"},
        {pos: [3, 3, 2], state: "minecraft:air"},
        {pos: [3, 3, 3], state: "minecraft:air"},
        {pos: [3, 3, 4], state: "minecraft:bedrock"},
        {pos: [4, 3, 0], state: "minecraft:bedrock"},
        {pos: [4, 3, 1], state: "minecraft:bedrock"},
        {pos: [4, 3, 2], state: "minecraft:bedrock"},
        {pos: [4, 3, 3], state: "minecraft:bedrock"},
        {pos: [4, 3, 4], state: "minecraft:bedrock"},
        {pos: [0, 4, 0], state: "minecraft:bedrock"},
        {pos: [0, 4, 1], state: "minecraft:bedrock"},
        {pos: [0, 4, 2], state: "minecraft:bedrock"},
        {pos: [0, 4, 3], state: "minecraft:bedrock"},
        {pos: [0, 4, 4], state: "minecraft:bedrock"},
        {pos: [1, 4, 0], state: "minecraft:bedrock"},
        {pos: [1, 4, 1], state: "minecraft:bedrock"},
        {pos: [1, 4, 2], state: "technicresources:glowrock"},
        {pos: [1, 4, 3], state: "minecraft:bedrock"},
        {pos: [1, 4, 4], state: "minecraft:bedrock"},
        {pos: [2, 4, 0], state: "minecraft:bedrock"},
        {pos: [2, 4, 1], state: "technicresources:glowrock"},
        {pos: [2, 4, 2], state: "minecraft:bedrock"},
        {pos: [2, 4, 3], state: "technicresources:glowrock"},
        {pos: [2, 4, 4], state: "minecraft:bedrock"},
        {pos: [3, 4, 0], state: "minecraft:bedrock"},
        {pos: [3, 4, 1], state: "minecraft:bedrock"},
        {pos: [3, 4, 2], state: "technicresources:glowrock"},
        {pos: [3, 4, 3], state: "minecraft:bedrock"},
        {pos: [3, 4, 4], state: "minecraft:bedrock"},
        {pos: [4, 4, 0], state: "minecraft:bedrock"},
        {pos: [4, 4, 1], state: "minecraft:bedrock"},
        {pos: [4, 4, 2], state: "minecraft:bedrock"},
        {pos: [4, 4, 3], state: "minecraft:bedrock"},
        {pos: [4, 4, 4], state: "minecraft:bedrock"}
    ],
    entities: [],
    palette: [
        "minecraft:bedrock",
        "technicresources:glowrock",
        "technicresources:bedrock_room_manager{stage:0}",
        "minecraft:air"
    ]
}